Workbook

Sheet Instrucciones
A1: StockPilot — Modelo financiero a 5 años
A2: Práctica de Ingeniería V · Formato de las preguntas 21 a 26 de la guía del Fondo Emprender
A4: Cómo usar el modelo
A5: 1. Todos los supuestos están en la hoja "Supuestos". Solo se editan las celdas en azul; las de fondo amarillo son los supuestos clave.
A6: 2. Las hojas "Pesimista", "Base" y "Optimista" calculan mes a mes (60 meses) y resumen por año. No se editan: todo son fórmulas.
A7: 3. La hoja "Resumen" muestra el escenario elegido en Supuestos!C5 (1 = Pesimista, 2 = Base, 3 = Optimista) con la estructura del Fondo Emprender.
A8: 4. La hoja "Comparación" pone los tres escenarios lado a lado.
A9: 5. Supuestos!C8 define cómo crece el equipo: 1 = según la carga de trabajo (recomendado); 2 = calendario de contratación del plan de negocio original.
A11: Convenciones de color
A12: Azul: dato de entrada editable · Negro: fórmula · Verde: vínculo a otra hoja · Fondo amarillo: supuesto clave.
A14: Cómo se calcula la nómina
A15: Costo mensual de un empleado = salario × (1 + aportes del empleador + prestaciones) + auxilio de transporte × (1 + prestaciones que lo incluyen), si el salario es ≤ 2 SMMLV.
... A30: Trabajo desde casa y equipos (v2): mientras los fundadores no cobran, el proyecto les reembolsa la energía y la parte del internet del hogar que usan para trabajar; además reserva cada mes el costo de reponer sus portátiles (vida útil de 5 años) y compra un portátil por cada colaborador nuevo. Desde el mes con salario, el auxilio de conectividad (mismo valor que el de transporte ya incluido en la nómina) cubre la energía y el internet. Supuestos en Supuestos!A82:F89.

Sheet Supuestos
A1: Supuestos del modelo
A2: Editar solo las celdas en azul. Cada supuesto tiene su fuente o justificación en la columna F.
A4: Controles
A5: Escenario que muestra la hoja Resumen | C5: 2 | F5: 1 = Pesimista, 2 = Base, 3 = Optimista
A8: Modo de crecimiento del equipo | C8: 1 | F8: 1 = según carga de trabajo (recomendado); 2 = calendario del plan de negocio original
A10: Supuestos por escenario | C10: Pesimista | D10: Base | E10: Optimista
A11: Clientes activos al cierre del año 1 | C11: 60 | D11: 120 | E11: 150 | F11: Base: meta del Plan de Negocio
A12: Clientes activos al cierre del año 2 | C12: 150 | D12: 300 | E12: 400 | F12: Base: SOM año 2 del Plan de Negocio
A13: Clientes activos al cierre del año 3 | C13: 300 | D13: 600 | E13: 800 | F13: Base: SOM año 3 del Plan de Negocio
A14: Clientes activos al cierre del año 4 | C14: 450 | D14: 900 | E14: 1200 | F14: Supuesto: inicio de expansión a otras ciudades
A15: Clientes activos al cierre del año 5 | C15: 600 | D15: 1200 | E15: 1600 | F15: Supuesto: ≈ 2,7 % de las tiendas de Bogotá en el escenario base
A16: Abandono mensual de clientes (churn) | C16: 0.05 | D16: 0.03 | E16: 0.02 | F16: El plan usa 5 % mensual y 90 % anual en secciones distintas; 3 % es un punto intermedio
A17: Marketing por cliente nuevo (CAC sin salarios) | C17: 100000 | D17: 65000 | E17: 50000 | F17: Base calibrada para que el año 1 cueste ≈ $9M, como en el Plan de Negocio (tabla 17.3)
A18: Mes en que los fundadores empiezan a recibir salario | C18: 37 | D18: 25 | E18: 25 | F18: Mes 25 = inicio del año 3
A20: Rampa de clientes del año 1 (fracción de la meta del año 1 al cierre de cada mes)
A21: Mes | C21: 1 | D21: 2 | E21: 3 | F21: 4 | G21: 5 | H21: 6 | I21: 7 | J21: 8 | K21: 9 | L21: 10 | M21: 11 | N21: 12
A22: Fracción de la meta del año 1 | C22: 0.0833 | D22: 0.125 | E22: 0.2083 | F22: 0.2917 | G22: 0.375 | H22: 0.4583 | I22: 0.5417 | J22: 0.6667 | K22: 0.75 | L22: 0.8333 | M22: 0.9167 | N22: 1
A23: Fuente: tabla 8.2 del Plan de Negocio (10 clientes en el mes 1 hasta 120 en el mes 12).
A25: Ingresos
A26: Precio mensual por tienda (año 1, sin IVA) | B26: COP/mes | C26: 39900 | F26: Plan de Negocio; igual al plan Esencial de Treinta
A27: Ajuste anual del precio | B27: % | C27: 0.05 | F27: Supuesto: ajuste cercano a la inflación
A28: Costos variables
A29: Costo de IA (OpenAI) por cliente activo | B29: COP/mes | C29: 1250 | F29: Plan de Negocio: $150.000/mes para 120 clientes
A30: Comisión de pasarela de pagos | B30: % ingreso | C30: 0.03 | F30: Supuesto (Wompi/PayU); no estaba en el plan
A31: Infraestructura en la nube hasta el umbral 1 | B31: COP/mes | C31: 220000 | F31: Plan de Negocio: Render + Neon
A32: Umbral 1 de clientes | B32: clientes | C32: 300 | F32: Supuesto
A33: Infraestructura en la nube hasta el umbral 2 | B33: COP/mes | C33: 450000 | F33: Supuesto: plan superior de base de datos y servidor
A34: Umbral 2 de clientes | B34: clientes | C34: 700 | F34: Supuesto
A35: Infraestructura en la nube por encima del umbral 2 | B35: COP/mes | C35: 800000 | F35: Supuesto
A36: Nómina
A37: SMMLV 2026 | B37: COP/mes | C37: 1750905 | F37: Infobae, 14-abr-2026 (decreto en litigio; actualizar si cambia)
A38: Auxilio de transporte 2026 | B38: COP/mes | C38: 249095 | F38: Infobae, 14-abr-2026. Aplica a salarios ≤ 2 SMMLV
A39: Ajuste anual de salarios, SMMLV y gastos | B39: % | C39: 0.05 | F39: Supuesto: ajuste cercano a la inflación
A40: Aporte a pensión (empleador) | B40: % salario | C40: 0.12 | F40: Ley 100 de 1993
A41: ARL riesgo I | B41: % salario | C41: 0.00522 | F41: Decreto 1772 de 1994
A42: Caja de compensación | B42: % salario | C42: 0.04 | F42: Ley 21 de 1982
A43: Salud, SENA e ICBF (empleador) | B43: % salario | C43: 0 | F43: Exoneración art. 114-1 ET para SAS con salarios < 10 SMMLV; verificar con contador
A44: Cesantías | B44: % salario | C44: 0.0833 | F44: Código Sustantivo del Trabajo
A45: Intereses sobre cesantías | B45: % salario | C45: 0.01 | F45: 12 % anual sobre las cesantías
A46: Prima de servicios | B46: % salario | C46: 0.0833 | F46: Código Sustantivo del Trabajo
...

Sheet Resumen
A1: Proyección financiera a 5 años — escenario seleccionado
A2: ="Escenario: "&CHOOSE(Supuestos!$C$5,"Pesimista","Base","Optimista")&" · Modo de equipo: "&IF(Supuestos!$C$8=1,"según carga de trabajo","calendario del plan original") -> Escenario: Base · Modo de equipo: según carga de trabajo
A3: Millones de COP salvo indicación. Cambie el escenario en Supuestos!C5.
A5: 21. Proyección de ingresos
A6: Concepto | B6: Año 0 | C6: Año 1 | D6: Año 2 | E6: Año 3 | F6: Año 4 | G6: Año 5
A7: Clientes activos al cierre | C7: =CHOOSE(Supuestos!$C$5,Pesimista!C53,Base!C53,Optimista!C53) -> 120 | D7: =CHOOSE(Supuestos!$C$5,Pesimista!D53,Base!D53,Optimista!D53) -> 300 | E7: =CHOOSE(Supuestos!$C$5,Pesimista!E53,Base!E53,Optimista!E53) -> 600 | F7: =CHOOSE(Supuestos!$C$5,Pesimista!F53,Base!F53,Optimista!F53) -> 900 | G7: =CHOOSE(Supuestos!$C$5,Pesimista!G53,Base!G53,Optimista!G53) -> 1200
A8: Clientes nuevos | C8: =CHOOSE(Supuestos!$C$5,Pesimista!C54,Base!C54,Optimista!C54) -> 138.9 | D8: =CHOOSE(Supuestos!$C$5,Pesimista!D54,Base!D54,Optimista!D54) -> 252.9 | E8: =CHOOSE(Supuestos!$C$5,Pesimista!E54,Base!E54,Optimista!E54) -> 457.5 | F8: =CHOOSE(Supuestos!$C$5,Pesimista!F54,Base!F54,Optimista!F54) -> 565.5 | G8: =CHOOSE(Supuestos!$C$5,Pesimista!G54,Base!G54,Optimista!G54) -> 673.5
A9: Clientes retirados | C9: =CHOOSE(Supuestos!$C$5,Pesimista!C55,Base!C55,Optimista!C55) -> 18.9 | D9: =CHOOSE(Supuestos!$C$5,Pesimista!D55,Base!D55,Optimista!D55) -> 72.9 | E9: =CHOOSE(Supuestos!$C$5,Pesimista!E55,Base!E55,Optimista!E55) -> 157.5 | F9: =CHOOSE(Supuestos!$C$5,Pesimista!F55,Base!F55,Optimista!F55) -> 265.5 | G9: =CHOOSE(Supuestos!$C$5,Pesimista!G55,Base!G55,Optimista!G55) -> 373.5
A10: Precio mensual (COP) | C10: =CHOOSE(Supuestos!$C$5,Pesimista!C56,Base!C56,Optimista!C56) -> 39900 | D10: =CHOOSE(Supuestos!$C$5,Pesimista!D56,Base!D56,Optimista!D56) -> 41895 | E10: =CHOOSE(Supuestos!$C$5,Pesimista!E56,Base!E56,Optimista!E56) -> 43989.75 | F10: =CHOOSE(Supuestos!$C$5,Pesimista!F56,Base!F56,Optimista!F56) -> 46189.238 | G10: =CHOOSE(Supuestos!$C$5,Pesimista!G56,Base!G56,Optimista!G56) -> 48498.699
A11: Ingresos | C11: =CHOOSE(Supuestos!$C$5,Pesimista!C57,Base!C57,Optimista!C57) -> 29.925 | D11: =CHOOSE(Supuestos!$C$5,Pesimista!D57,Base!D57,Optimista!D57) -> 109.34595 | E11: =CHOOSE(Supuestos!$C$5,Pesimista!E57,Base!E57,Optimista!E57) -> 244.14311 | F11: =CHOOSE(Supuestos!$C$5,Pesimista!F57,Base!F57,Optimista!F57) -> 422.63152 | G11: =CHOOSE(Supuestos!$C$5,Pesimista!G57,Base!G57,Optimista!G57) -> 618.35842
A13: 22. Proyección de costos
A14: Concepto | B14: Año 0 | C14: Año 1 | D14: Año 2 | E14: Año 3 | F14: Año 4 | G14: Año 5
A15: Costos de operación del servicio (IA, pasarela, nube) | C15: =CHOOSE(Supuestos!$C$5,Pesimista!C58,Base!C58,Optimista!C58) -> 4.47525 | D15: =CHOOSE(Supuestos!$C$5,Pesimista!D58,Base!D58,Optimista!D58) -> 9.3460035 | E15: =CHOOSE(Supuestos!$C$5,Pesimista!E58,Base!E58,Optimista!E58) -> 20.372887 | F15: =CHOOSE(Supuestos!$C$5,Pesimista!F58,Base!F58,Optimista!F58) -> 34.119282 | G15: =CHOOSE(Supuestos!$C$5,Pesimista!G58,Base!G58,Optimista!G58) -> 47.522883
A16: Margen bruto | C16: =CHOOSE(Supuestos!$C$5,Pesimista!C59,Base!C59,Optimista!C59) -> 25.44975 | D16: =CHOOSE(Supuestos!$C$5,Pesimista!D59,Base!D59,Optimista!D59) -> 99.999946 | E16: =CHOOSE(Supuestos!$C$5,Pesimista!E59,Base!E59,Optimista!E59) -> 223.77023 | F16: =CHOOSE(Supuestos!$C$5,Pesimista!F59,Base!F59,Optimista!F59) -> 388.51224 | G16: =CHOOSE(Supuestos!$C$5,Pesimista!G59,Base!G59,Optimista!G59) -> 570.83553
A17: Margen bruto (%) | C17: =CHOOSE(Supuestos!$C$5,Pesimista!C60,Base!C60,Optimista!C60) -> 0.85045113 | D17: =CHOOSE(Supuestos!$C$5,Pesimista!D60,Base!D60,Optimista!D60) -> 0.91452812 | E17: =CHOOSE(Supuestos!$C$5,Pesimista!E60,Base!E60,Optimista!E60) -> 0.9165535 | F17: =CHOOSE(Supuestos!$C$5,Pesimista!F60,Base!F60,Optimista!F60) -> 0.91926944 | G17: =CHOOSE(Supuestos!$C$5,Pesimista!G60,Base!G60,Optimista!G60) -> 0.9231467
A19: 23. Proyección de gastos
A20: Concepto | B20: Año 0 | C20: Año 1 | D20: Año 2 | E20: Año 3 | F20: Año 4 | G20: Año 5
A21: Nómina de colaboradores | C21: =CHOOSE(Supuestos!$C$5,Pesimista!C61,Base!C61,Optimista!C61) -> 0 | D21: =CHOOSE(Supuestos!$C$5,Pesimista!D61,Base!D61,Optimista!D61) -> 0 | E21: =CHOOSE(Supuestos!$C$5,Pesimista!E61,Base!E61,Optimista!E61) -> 20.242728 | F21: =CHOOSE(Supuestos!$C$5,Pesimista!F61,Base!F61,Optimista!F61) -> 63.764593 | G21: =CHOOSE(Supuestos!$C$5,Pesimista!G61,Base!G61,Optimista!G61) -> 115.30764
A22: Nómina de fundadores | C22: =CHOOSE(Supuestos!$C$5,Pesimista!C62,Base!C62,Optimista!C62) -> 0 | D22: =CHOOSE(Supuestos!$C$5,Pesimista!D62,Base!D62,Optimista!D62) -> 0 | E22: =CHOOSE(Supuestos!$C$5,Pesimista!E62,Base!E62,Optimista!E62) -> 176.36828 | F22: =CHOOSE(Supuestos!$C$5,Pesimista!F62,Base!F62,Optimista!F62) -> 185.18669 | G22: =CHOOSE(Supuestos!$C$5,Pesimista!G62,Base!G62,Optimista!G62) -> 194.44603
A23: Marketing y adquisición | C23: =CHOOSE(Supuestos!$C$5,Pesimista!C63,Base!C63,Optimista!C63) -> 9.0285 | D23: =CHOOSE(Supuestos!$C$5,Pesimista!D63,Base!D63,Optimista!D63) -> 17.260425 | E23: =CHOOSE(Supuestos!$C$5,Pesimista!E63,Base!E63,Optimista!E63) -> 32.785594 | F23: =CHOOSE(Supuestos!$C$5,Pesimista!F63,Base!F63,Optimista!F63) -> 42.551401 | G23: =CHOOSE(Supuestos!$C$5,Pesimista!G63,Base!G63,Optimista!G63) -> 53.211825
A24: Arriendo, administración, software, equipos y trabajo desde casa | C24: =CHOOSE(Supuestos!$C$5,Pesimista!C64,Base!C64,Optimista!C64) -> 5.7665398 | D24: =CHOOSE(Supuestos!$C$5,Pesimista!D64,Base!D64,Optimista!D64) -> 8.6218001 | E24: =CHOOSE(Supuestos!$C$5,Pesimista!E64,Base!E64,Optimista!E64) -> 17.5203 | F24: =CHOOSE(Supuestos!$C$5,Pesimista!F64,Base!F64,Optimista!F64) -> 18.396315 | G24: =CHOOSE(Supuestos!$C$5,Pesimista!G64,Base!G64,Optimista!G64) -> 19.316131
A25: Total gastos operativos | C25: =CHOOSE(Supuestos!$C$5,Pesimista!C65,Base!C65,Optimista!C65) -> 14.79504 | D25: =CHOOSE(Supuestos!$C$5,Pesimista!D65,Base!D65,Optimista!D65) -> 25.882225 | E25: =CHOOSE(Supuestos!$C$5,Pesimista!E65,Base!E65,Optimista!E65) -> 246.9169 | F25: =CHOOSE(Supuestos!$C$5,Pesimista!F65,Base!F65,Optimista!F65) -> 309.899 | G25: =CHOOSE(Supuestos!$C$5,Pesimista!G65,Base!G65,Optimista!G65) -> 382.28162
A26: Resultado operativo (EBITDA) | C26: =CHOOSE(Supuestos!$C$5,Pesimista!C66,Base!C66,Optimista!C66) -> 10.65471 | D26: =CHOOSE(Supuestos!$C$5,Pesimista!D66,Base!D66,Optimista!D66) -> 74.117721 | E26: =CHOOSE(Supuestos!$C$5,Pesimista!E66,Base!E66,Optimista!E66) -> -23.146673 | F26: =CHOOSE(Supuestos!$C$5,Pesimista!F66,Base!F66,Optimista!F66) -> 78.613241 | G26: =CHOOSE(Supuestos!$C$5,Pesimista!G66,Base!G66,Optimista!G66) -> 188.55391
A27: Impuesto de renta | C27: =CHOOSE(Supuestos!$C$5,Pesimista!C69,Base!C69,Optimista!C69) -> 3.7291486 | D27: =CHOOSE(Supuestos!$C$5,Pesimista!D69,Base!D69,Optimista!D69) -> 25.941202 | E27: =CHOOSE(Supuestos!$C$5,Pesimista!E69,Base!E69,Optimista!E69) -> 0 | F27: =CHOOSE(Supuestos!$C$5,Pesimista!F69,Base!F69,Optimista!F69) -> 19.413299 | G27: =CHOOSE(Supuestos!$C$5,Pesimista!G69,Base!G69,Optimista!G69) -> 65.99387
A28: Utilidad neta | C28: =CHOOSE(Supuestos!$C$5,Pesimista!C70,Base!C70,Optimista!C70) -> 6.9255617 | D28: =CHOOSE(Supuestos!$C$5,Pesimista!D70,Base!D70,Optimista!D70) -> 48.176519 | E28: =CHOOSE(Supuestos!$C$5,Pesimista!E70,Base!E70,Optimista!E70) -> -23.146673 | F28: =CHOOSE(Supuestos!$C$5,Pesimista!F70,Base!F70,Optimista!F70) -> 59.199943 | G28: =CHOOSE(Supuestos!$C$5,Pesimista!G70,Base!G70,Optimista!G70) -> 122.56004
A29: Flujo de caja neto | B29: =CHOOSE(Supuestos!$C$5,Pesimista!B71,Base!B71,Optimista!B71) -> -1.5 | C29: =CHOOSE(Supuestos!$C$5,Pesimista!C71,Base!C71,Optimista!C71) -> 6.9255617 | D29: =CHOOSE(Supuestos!$C$5,Pesimista!D71,Base!D71,Optimista!D71) -> 48.176519 | E29: =CHOOSE(Supuestos!$C$5,Pesimista!E71,Base!E71,Optimista!E71) -> -23.146673 | F29: =CHOOSE(Supuestos!$C$5,Pesimista!F71,Base!F71,Optimista!F71) -> 59.199943 | G29: =CHOOSE(Supuestos!$C$5,Pesimista!G71,Base!G71,Optimista!G71) -> 122.56004
A30: Flujo de caja acumulado | B30: =CHOOSE(Supuestos!$C$5,Pesimista!B72,Base!B72,Optimista!B72) -> -1.5 | C30: =CHOOSE(Supuestos!$C$5,Pesimista!C72,Base!C72,Optimista!C72) -> 5.4255617 | D30: =CHOOSE(Supuestos!$C$5,Pesimista!D72,Base!D72,Optimista!D72) -> 53.602081 | E30: =CHOOSE(Supuestos!$C$5,Pesimista!E72,Base!E72,Optimista!E72) -> 30.455407 | F30: =CHOOSE(Supuestos!$C$5,Pesimista!F72,Base!F72,Optimista!F72) -> 89.65535 | G30: =CHOOSE(Supuestos!$C$5,Pesimista!G72,Base!G72,Optimista!G72) -> 212.21539
A31: Memo: trabajo no remunerado de los fundadores (aporte en especie) | C31: =CHOOSE(Supuestos!$C$5,Pesimista!C74,Base!C74,Optimista!C74) -> 79.985613 | D31: =CHOOSE(Supuestos!$C$5,Pesimista!D74,Base!D74,Optimista!D74) -> 125.97734 | E31: =CHOOSE(Supuestos!$C$5,Pesimista!E74,Base!E74,Optimista!E74) -> 0 | F31: =CHOOSE(Supuestos!$C$5,Pesimista!F74,Base!F74,Optimista!F74) -> 0 | G31: =CHOOSE(Supuestos!$C$5,Pesimista!G74,Base!G74,Optimista!G74) -> 0
A32: Personas en el equipo al cierre | C32: =CHOOSE(Supuestos!$C$5,Pesimista!C75,Base!C75,Optimista!C75) -> 3 | D32: =CHOOSE(Supuestos!$C$5,Pesimista!D75,Base!D75,Optimista!D75) -> 3 | E32: =CHOOSE(Supuestos!$C$5,Pesimista!E75,Base!E75,Optimista!E75) -> 4 | F32: =CHOOSE(Supuestos!$C$5,Pesimista!F75,Base!F75,Optimista!F75) -> 5 | G32: =CHOOSE(Supuestos!$C$5,Pesimista!G75,Base!G75,Optimista!G75) -> 6
A33: Punto de equilibrio (clientes activos) | C33: =CHOOSE(Supuestos!$C$5,Pesimista!C77,Base!C77,Optimista!C77) -> 39 | D33: =CHOOSE(Supuestos!$C$5,Pesimista!D77,Base!D77,Optimista!D77) -> 61 | E33: =CHOOSE(Supuestos!$C$5,Pesimista!E77,Base!E77,Optimista!E77) -> 510 | F33: =CHOOSE(Supuestos!$C$5,Pesimista!F77,Base!F77,Optimista!F77) -> 612 | G33: =CHOOSE(Supuestos!$C$5,Pesimista!G77,Base!G77,Optimista!G77) -> 718
A35: 24. Inversiones (COP)
A36: Gastos preoperativos | B36: =Supuestos!$C$71 -> 500000
A37: Marketing inicial | B37: =Supuestos!$C$72 -> 1000000
A38: Equipos de cómputo (aporte en especie) | B38: =Supuestos!$C$73 -> 0
A39: Total inversión inicial | B39: =SUM(B36:B38) -> 1500000
A41: 25. Capital de trabajo e indicadores
A42: VPN a la TIO (millones COP) | B42: =CHOOSE(Supuestos!$C$5,Pesimista!C80,Base!C80,Optimista!C80) -> 102.13564
A43: TIR | B43: =CHOOSE(Supuestos!$C$5,Pesimista!C81,Base!C81,Optimista!C81) -> 7.333862
A44: Año de recuperación de la inversión | B44: =CHOOSE(Supuestos!$C$5,Pesimista!C82,Base!C82,Optimista!C82) -> 1
A45: Necesidad máxima de caja (millones COP) | B45: =CHOOSE(Supuestos!$C$5,Pesimista!C83,Base!C83,Optimista!C83) -> 3.4915691
...

Sheet Comparación
A1: Comparación de escenarios
A2: ="Modo de equipo: "&IF(Supuestos!$C$8=1,"según carga de trabajo","calendario del plan original") -> Modo de equipo: según carga de trabajo
A4: Indicador | B4: Pesimista | C4: Base | D4: Optimista
A5: Clientes activos al cierre del año 5 | B5: =Pesimista!G53 -> 600 | C5: =Base!G53 -> 1200 | D5: =Optimista!G53 -> 1600
A6: Ingresos año 1 (millones COP) | B6: =Pesimista!C57 -> 14.9625 | C6: =Base!C57 -> 29.925 | D6: =Optimista!C57 -> 37.40625
A7: Ingresos año 5 (millones COP) | B7: =Pesimista!G57 -> 309.17921 | C7: =Base!G57 -> 618.35842 | D7: =Optimista!G57 -> 824.47789
A8: Utilidad neta año 1 (millones COP) | B8: =Pesimista!C70 -> -1.9366648 | C8: =Base!C70 -> 6.9255617 | D8: =Optimista!C70 -> 11.971796
A9: Utilidad neta año 5 (millones COP) | B9: =Pesimista!G70 -> -18.486027 | C9: =Base!G70 -> 122.56004 | D9: =Optimista!G70 -> 224.97898
A10: Trabajo no remunerado de fundadores, 5 años (millones COP) | B10: =SUM(Pesimista!C74:G74) -> 382.33123 | C10: =SUM(Base!C74:G74) -> 205.96295 | D10: =SUM(Optimista!C74:G74) -> 205.96295
A11: Personas en el equipo al cierre del año 5 | B11: =Pesimista!G75 -> 4 | C11: =Base!G75 -> 6 | D11: =Optimista!G75 -> 7
A12: VPN a la TIO (millones COP) | B12: =Pesimista!C80 -> 0.84796043 | C12: =Base!C80 -> 102.13564 | D12: =Optimista!C80 -> 206.6355
A13: TIR | B13: =Pesimista!C81 -> 0.17689002 | C13: =Base!C81 -> 7.333862 | D13: =Optimista!C81 -> 10.528371
A14: Año de recuperación de la inversión | B14: =Pesimista!C82 -> 2 | C14: =Base!C82 -> 1 | D14: =Optimista!C82 -> 1
A15: Necesidad máxima de caja (millones COP) | B15: =Pesimista!C83 -> 5.5498048 | C15: =Base!C83 -> 3.4915691 | D15: =Optimista!C83 -> 2.854692
A16: Primer mes con resultado operativo positivo | B16: =Pesimista!C84 -> 9 | C16: =Base!C84 -> 5 | D16: =Optimista!C84 -> 4

Sheet Pesimista
A1: Escenario Pesimista — proyección mensual (60 meses) y anual
A2: Índice del escenario | B2: 1
A3: Todo en esta hoja es fórmula. Para cambiar resultados, edite la hoja Supuestos.
A5: Mes | C5: 1 | D5: 2 | E5: 3 | F5: 4 | G5: 5 | H5: 6 | I5: 7 | J5: 8 | K5: 9 | L5: 10 | M5: 11 | N5: 12 | O5: 13 | P5: 14 | Q5: 15 | R5: 16 | S5: 17 | T5: 18 | U5: 19 | V5: 20 | W5: 21 | X5: 22 | Y5: 23 | Z5: 24 | AA5: 25 | AB5: 26 | AC5: 27 | AD5: 28 | AE5: 29 | AF5: 30 | AG5: 31 | AH5: 32 | AI5: 33 | AJ5: 34 | AK5: 35 | AL5: 36 | AM5: 37 | AN5: 38 | AO5: 39 | AP5: 40 | AQ5: 41 | AR5: 42 | AS5: 43 | AT5: 44 | AU5: 45 | AV5: 46 | AW5: 47 | AX5: 48 | AY5: 49 | AZ5: 50 | BA5: 51 | BB5: 52 | BC5: 53 | BD5: 54 | BE5: 55 | BF5: 56 | BG5: 57 | BH5: 58 | BI5: 59 | BJ5: 60
A6: Año | C6: =ROUNDUP(C5/12,0) -> 1 | D6: =ROUNDUP(D5/12,0) -> 1 | E6: =ROUNDUP(E5/12,0) -> 1 | F6: =ROUNDUP(F5/12,0) -> 1 | G6: =ROUNDUP(G5/12,0) -> 1 | H6: =ROUNDUP(H5/12,0) -> 1 | I6: =ROUNDUP(I5/12,0) -> 1 | J6: =ROUNDUP(J5/12,0) -> 1 | ... BJ6: =ROUNDUP(BJ5/12,0) -> 5
A7: Mes del año | C7: =C5-(C6-1)*12 -> 1 | D7: =D5-(D6-1)*12 -> 2 | E7: =E5-(E6-1)*12 -> 3 | F7: =F5-(F6-1)*12 -> 4 | G7: =G5-(G6-1)*12 -> 5 | H7: =H5-(H6-1)*12 -> 6 | I7: =I5-(I6-1)*12 -> 7 | J7: =J5-(J6-1)*12 -> 8 | ... BJ7: =BJ5-(BJ6-1)*12 -> 12
A9: Clientes
A10: Meta de clientes activos al cierre del mes | B10: clientes | C10: =IF(C6=1,INDEX(Supuestos!$C$22:$N$22,1,C7)*INDEX(Supuestos!$C$11:$E$11,1,$B$2),IF(C6=2,INDEX(Supuestos!$C$11:$E$11,1,$B$2),IF(C6=3,INDEX(Supuestos!$C$12:$E$12,1,$B$2),IF(C6=4,INDEX(Supuestos!$C$13:$E$13,1,$B$2),INDEX(Supuestos!$C$14:$E$14,1,$B$2))))+(IF(C6=2,INDEX(Supuestos!$C$12:$E$12,1,$B$2),IF(C6=3,INDEX(Supuestos!$C$13:$E$13,1,$B$2),IF(C6=4,INDEX(Supuestos!$C$14:$E$14,1,$B$2),INDEX(Supuestos!$C$15:$E$15,1,$B$2))))-IF(C6=2,INDEX(Supuestos!$C$11:$E$11,1,$B$2),IF(C6=3,INDEX(Supuestos!$C$12:$E$12,1,$B$2),IF(C6=4,INDEX(Supuestos!$C$13:$E$13,1,$B$2),INDEX(Supuestos!$C$14:$E$14,1,$B$2)))))*C7/12) -> 4.998 | D10: =IF(D6=1,INDEX(Supuestos!$C$22:$N$22,1,D7)*INDEX(Supuestos!$C$11:$E$11,1,$B$2),IF(D6=2,INDEX(Supuestos!$C$11:$E$11,1,$B$2),IF(D6=3,INDEX(Supuestos!$C$12:$E$12,1,$B$2),IF(D6=4,INDEX(Supuestos!$C$13:$E$13,1,$B$2),INDEX(Supuestos!$C$14:$E$14,1,$B$2))))+(IF(D6=2,INDEX(Supuestos!$C$12:$E$12,1,$B$2),IF(D6=3,INDEX(Supuestos!$C$13:$E$13,1,$B$2),IF(D6=4,INDEX(Supuestos!$C$14:$E$14,1,$B$2),INDEX(Supuestos!$C$15:$E$15,1,$B$2))))-IF(D6=2,INDEX(Supuestos!$C$11:$E$11,1,$B$2),IF(D6=3,INDEX(Supuestos!$C$12:$E$12,1,$B$2),IF(D6=4,INDEX(Supuestos!$C$13:$E$13,1,$B$2),INDEX(Supuestos!$C$14:$E$14,1,$B$2)))))*D7/12) -> 7.5 | E10: =IF(E6=1,INDEX(Supuestos!$C$22:$N$22,1,E7)*INDEX(Supuestos!$C$11:$E$11,1,$B$2),IF(E6=2,INDEX(Supuestos!$C$11:$E$11,1,$B$2),IF(E6=3,INDEX(Supuestos!$C$12:$E$12,1,$B$2),IF(E6=4,INDEX(Supuestos!$C$13:$E$13,1,$B$2),INDEX(Supuestos!$C$14:$E$14,1,$B$2))))+(IF(E6=2,INDEX(Supuestos!$C$12:$E$12,1,$B$2),IF(E6=3,INDEX(Supuestos!$C$13:$E$13,1,$B$2),IF(E6=4,INDEX(Supuestos!$C$14:$E$14,1,$B$2),INDEX(Supuestos!$C$15:$E$15,1,$B$2))))-IF(E6=2,INDEX(Supuestos!$C$11:$E$11,1,$B$2),IF(E6=3,INDEX(Supuestos!$C$12:$E$12,1,$B$2),IF(E6=4,INDEX(Supuestos!$C$13:$E$13,1,$B$2),INDEX(Supuestos!$C$14:$E$14,1,$B$2)))))*E7/12) -> 12.498 | F10: =IF(F6=1,INDEX(Supuestos!$C$22:$N$22,1,F7)*INDEX(Supuestos!$C$11:$E$11,1,$B$2),IF(F6=2,INDEX(Supuestos!$C$11:$E$11,1,$B$2),IF(F6=3,INDEX(Supuestos!$C$12:$E$12,1,$B$2),IF(F6=4,INDEX(Supuestos!$C$13:$E$13,1,$B$2),INDEX(Supuestos!$C$14:$E$14,1,$B$2))))+(IF(F6=2,INDEX(Supuestos!$C$12:$E$12,1,$B$2),IF(F6=3,INDEX(Supuestos!$C$13:$E$13,1,$B$2),IF(F6=4,INDEX(Supuestos!$C$14:$E$14,1,$B$2),INDEX(Supuestos!$C$15:$E$15,1,$B$2))))-IF(F6=2,INDEX(Supuestos!$C$11:$E$11,1,$B$2),IF(F6=3,INDEX(Supuestos!$C$12:$E$12,1,$B$2),IF(F6=4,INDEX(Supuestos!$C$13:$E$13,1,$B$2),INDEX(Supuestos!$C$14:$E$14,1,$B$2)))))*F7/12) -> 17.502 | G10: =IF(G6=1,INDEX(Supuestos!$C$22:$N$22,1,G7)*INDEX(Supuestos!$C$11:$E$11,1,$B$2),IF(G6=2,INDEX(Supuestos!$C$11:$E$11,1,$B$2),IF(G6=3,INDEX(Supuestos!$C$12:$E$12,1,$B$2),IF(G6=4,INDEX(Supuestos!$C$13:$E$13,1,$B$2),INDEX(Supuestos!$C$14:$E$14,1,$B$2))))+(IF(G6=2,INDEX(Supuestos!$C$12:$E$12,1,$B$2),IF(G6=3,INDEX(Supuestos!$C$13:$E$13,1,$B$2),IF(G6=4,INDEX(Supuestos!$C$14:$E$14,1,$B$2),INDEX(Supuestos!$C$15:$E$15,1,$B$2))))-IF(G6=2,INDEX(Supuestos!$C$11:$E$11,1,$B$2),IF(G6=3,INDEX(Supuestos!$C$12:$E$12,1,$B$2),IF(G6=4,INDEX(Supuestos!$C$13:$E$13,1,$B$2),INDEX(Supuestos!$C$14:$E$14,1,$B$2)))))*G7/12) -> 22.5 | H10: =IF(H6=1,INDEX(Supuestos!$C$22:$N$22,1,H7)*INDEX(Supuestos!$C$11:$E$11,1,$B$2),IF(H6=2,INDEX(Supuestos!$C$11:$E$11,1,$B$2),IF(H6=3,INDEX(Supuestos!$C$12:$E$12,1,$B$2),IF(H6=4,INDEX(Supuestos!$C$13:$E$13,1,$B$2),INDEX(Supuestos!$C$14:$E$14,1,$B$2))))+(IF(H6=2,INDEX(Supuestos!$C$12:$E$12,1,$B$2),IF(H6=3,INDEX(Supuestos!$C$13:$E$13,1,$B$2),IF(H6=4,INDEX(Supuestos!$C$14:$E$14,1,$B$2),INDEX(Supuestos!$C$15:$E$15,1,$B$2))))-IF(H6=2,INDEX(Supuestos!$C$11:$E$11,1,$B$2),IF(H6=3,INDEX(Supuestos!$C$12:$E$12,1,$B$2),IF(H6=4,INDEX(Supuestos!$C$13:$E$13,1,$B$2),INDEX(Supuestos!$C$14:$E$14,1,$B$2)))))*H7/12) -> 27.498 | I10: =IF(I6=1,INDEX(Supuestos!$C$22:$N$22,1,I7)*INDEX(Supuestos!$C$11:$E$11,1,$B$2),IF(I6=2,INDEX(Supuestos!$C$11:$E$11,1,$B$2),IF(I6=3,INDEX(Supuestos!$C$12:$E$12,1,$B$2),IF(I6=4,INDEX(Supuestos!$C$13:$E$13,1,$B$2),INDEX(Supuestos!$C$14:$E$14,1,$B$2))))+(IF(I6=2,INDEX(Supuestos!$C$12:$E$12,1,$B$2),IF(I6=3,INDEX(Supuestos!$C$13:$E$13,1,$B$2),IF(I6=4,INDEX(Supuestos!$C$14:$E$14,1,$B$2),INDEX(Supuestos!$C$15:$E$15,1,$B$2))))-IF(I6=2,INDEX(Supuestos!$C$11:$E$11,1,$B$2),IF(I6=3,INDEX(Supuestos!$C$12:$E$12,1,$B$2),IF(I6=4,INDEX(Supuestos!$C$13:$E$13,1,$B$2),INDEX(Supuestos!$C$14:$E$14,1,$B$2)))))*I7/12) -> 32.502 | J10: =IF(J6=1,INDEX(Supuestos!$C$22:$N$22,1,J7)*INDEX(Supuestos!$C$11:$E$11,1,$B$2),IF(J6=2,INDEX(Supuestos!$C$11:$E$11,1,$B$2),IF(J6=3,INDEX(Supuestos!$C$12:$E$12,1,$B$2),IF(J6=4,INDEX(Supuestos!$C$13:$E$13,1,$B$2),INDEX(Supuestos!$C$14:$E$14,1,$B$2))))+(IF(J6=2,INDEX(Supuestos!$C$12:$E$12,1,$B$2),IF(J6=3,INDEX(Supuestos!$C$13:$E$13,1,$B$2),IF(J6=4,INDEX(Supuestos!$C$14:$E$14,1,$B$2),INDEX(Supuestos!$C$15:$E$15,1,$B$2))))-IF(J6=2,INDEX(Supuestos!$C$11:$E$11,1,$B$2),IF(J6=3,INDEX(Supuestos!$C$12:$E$12,1,$B$2),IF(J6=4,INDEX(Supuestos!$C$13:$E$13,1,$B$2),INDEX(Supuestos!$C$14:$E$14,1,$B$2)))))*J7/12) -> 40.002 | ... BJ10: =IF(BJ6=1,INDEX(Supuestos!$C$22:$N$22,1,BJ7)*INDEX(Supuestos!$C$11:$E$11,1,$B$2),IF(BJ6=2,INDEX(Supuestos!$C$11:$E$11,1,$B$2),IF(BJ6=3,INDEX(Supuestos!$C$12:$E$12,1,$B$2),IF(BJ6=4,INDEX(Supuestos!$C$13:$E$13,1,$B$2),INDEX(Supuestos!$C$14:$E$14,1,$B$2))))+(IF(BJ6=2,INDEX(Supuestos!$C$12:$E$12,1,$B$2),IF(BJ6=3,INDEX(Supuestos!$C$13:$E$13,1,$B$2),IF(BJ6=4,INDEX(Supuestos!$C$14:$E$14,1,$B$2),INDEX(Supuestos!$C$15:$E$15,1,$B$2))))-IF(BJ6=2,INDEX(Supuestos!$C$11:$E$11,1,$B$2),IF(BJ6=3,INDEX(Supuestos!$C$12:$E$12,1,$B$2),IF(BJ6=4,INDEX(Supuestos!$C$13:$E$13,1,$B$2),INDEX(Supuestos!$C$14:$E$14,1,$B$2)))))*BJ7/12) -> 600
A11: Clientes al inicio del mes | B11: clientes | C11: 0 | D11: =C14 -> 4.998 | E11: =D14 -> 7.5 | F11: =E14 -> 12.498 | G11: =F14 -> 17.502 | H11: =G14 -> 22.5 | I11: =H14 -> 27.498 | J11: =I14 -> 32.502 | K11: =J14 -> 40.002 | ... BJ11: =BI14 -> 587.5
A12: Clientes que se retiran | B12: clientes | C12: =C11*INDEX(Supuestos!$C$16:$E$16,1,$B$2) -> 0 | D12: =D11*INDEX(Supuestos!$C$16:$E$16,1,$B$2) -> 0.2499 | E12: =E11*INDEX(Supuestos!$C$16:$E$16,1,$B$2) -> 0.375 | F12: =F11*INDEX(Supuestos!$C$16:$E$16,1,$B$2) -> 0.6249 | G12: =G11*INDEX(Supuestos!$C$16:$E$16,1,$B$2) -> 0.8751 | H12: =H11*INDEX(Supuestos!$C$16:$E$16,1,$B$2) -> 1.125 | I12: =I11*INDEX(Supuestos!$C$16:$E$16,1,$B$2) -> 1.3749 | J12: =J11*INDEX(Supuestos!$C$16:$E$16,1,$B$2) -> 1.6251 | ... BJ12: =BJ11*INDEX(Supuestos!$C$16:$E$16,1,$B$2) -> 29.375
A13: Clientes nuevos | B13: clientes | C13: =MAX(0,C10-(C11-C12)) -> 4.998 | D13: =MAX(0,D10-(D11-D12)) -> 2.7519 | E13: =MAX(0,E10-(E11-E12)) -> 5.373 | F13: =MAX(0,F10-(F11-F12)) -> 5.6289 | G13: =MAX(0,G10-(G11-G12)) -> 5.8731 | H13: =MAX(0,H10-(H11-H12)) -> 6.123 | I13: =MAX(0,I10-(I11-I12)) -> 6.3789 | J13: =MAX(0,J10-(J11-J12)) -> 9.1251 | ... BJ13: =MAX(0,BJ10-(BJ11-BJ12)) -> 41.875
A14: Clientes activos al cierre del mes | B14: clientes | C14: =C11-C12+C13 -> 4.998 | D14: =D11-D12+D13 -> 7.5 | E14: =E11-E12+E13 -> 12.498 | F14: =F11-F12+F13 -> 17.502 | G14: =G11-G12+G13 -> 22.5 | H14: =H11-H12+H13 -> 27.498 | I14: =I11-I12+I13 -> 32.502 | J14: =J11-J12+J13 -> 40.002 | ... BJ14: =BJ11-BJ12+BJ13 -> 600
A16: Ingresos y costos variables
A17: Precio mensual por tienda | B17: COP | C17: =Supuestos!$C$26*(1+Supuestos!$C$27)^(C6-1) -> 39900 | D17: =Supuestos!$C$26*(1+Supuestos!$C$27)^(D6-1) -> 39900 | E17: =Supuestos!$C$26*(1+Supuestos!$C$27)^(E6-1) -> 39900 | F17: =Supuestos!$C$26*(1+Supuestos!$C$27)^(F6-1) -> 39900 | G17: =Supuestos!$C$26*(1+Supuestos!$C$27)^(G6-1) -> 39900 | H17: =Supuestos!$C$26*(1+Supuestos!$C$27)^(H6-1) -> 39900 | I17: =Supuestos!$C$26*(1+Supuestos!$C$27)^(I6-1) -> 39900 | J17: =Supuestos!$C$26*(1+Supuestos!$C$27)^(J6-1) -> 39900 | ... BJ17: =Supuestos!$C$26*(1+Supuestos!$C$27)^(BJ6-1) -> 48498.699
A18: Ingresos | B18: COP | C18: =C14*C17 -> 199420.2 | D18: =D14*D17 -> 299250 | E18: =E14*E17 -> 498670.2 | F18: =F14*F17 -> 698329.8 | G18: =G14*G17 -> 897750 | H18: =H14*H17 -> 1097170.2 | I18: =I14*I17 -> 1296829.8 | J18: =J14*J17 -> 1596079.8 | ... BJ18: =BJ14*BJ17 -> 29099220
A19: Costo de IA | B19: COP | C19: =C14*Supuestos!$C$29*(1+Supuestos!$C$39)^(C6-1) -> 6247.5 | D19: =D14*Supuestos!$C$29*(1+Supuestos!$C$39)^(D6-1) -> 9375 | E19: =E14*Supuestos!$C$29*(1+Supuestos!$C$39)^(E6-1) -> 15622.5 | F19: =F14*Supuestos!$C$29*(1+Supuestos!$C$39)^(F6-1) -> 21877.5 | G19: =G14*Supuestos!$C$29*(1+Supuestos!$C$39)^(G6-1) -> 28125 | H19: =H14*Supuestos!$C$29*(1+Supuestos!$C$39)^(H6-1) -> 34372.5 | I19: =I14*Supuestos!$C$29*(1+Supuestos!$C$39)^(I6-1) -> 40627.5 | J19: =J14*Supuestos!$C$29*(1+Supuestos!$C$39)^(J6-1) -> 50002.5 | ... BJ19: =BJ14*Supuestos!$C$29*(1+Supuestos!$C$39)^(BJ6-1) -> 911629.69
A20: Comisión de pasarela de pagos | B20: COP | C20: =C18*Supuestos!$C$30 -> 5982.606 | D20: =D18*Supuestos!$C$30 -> 8977.5 | E20: =E18*Supuestos!$C$30 -> 14960.106 | F20: =F18*Supuestos!$C$30 -> 20949.894 | G20: =G18*Supuestos!$C$30 -> 26932.5 | H20: =H18*Supuestos!$C$30 -> 32915.106 | I20: =I18*Supuestos!$C$30 -> 38904.894 | J20: =J18*Supuestos!$C$30 -> 47882.394 | ... BJ20: =BJ18*Supuestos!$C$30 -> 872976.59
A21: Infraestructura en la nube | B21: COP | C21: =IF(C14<=Supuestos!$C$32,Supuestos!$C$31,IF(C14<=Supuestos!$C$34,Supuestos!$C$33,Supuestos!$C$35)) -> 220000 | D21: =IF(D14<=Supuestos!$C$32,Supuestos!$C$31,IF(D14<=Supuestos!$C$34,Supuestos!$C$33,Supuestos!$C$35)) -> 220000 | E21: =IF(E14<=Supuestos!$C$32,Supuestos!$C$31,IF(E14<=Supuestos!$C$34,Supuestos!$C$33,Supuestos!$C$35)) -> 220000 | F21: =IF(F14<=Supuestos!$C$32,Supuestos!$C$31,IF(F14<=Supuestos!$C$34,Supuestos!$C$33,Supuestos!$C$35)) -> 220000 | G21: =IF(G14<=Supuestos!$C$32,Supuestos!$C$31,IF(G14<=Supuestos!$C$34,Supuestos!$C$33,Supuestos!$C$35)) -> 220000 | H21: =IF(H14<=Supuestos!$C$32,Supuestos!$C$31,IF(H14<=Supuestos!$C$34,Supuestos!$C$33,Supuestos!$C$35)) -> 220000 | I21: =IF(I14<=Supuestos!$C$32,Supuestos!$C$31,IF(I14<=Supuestos!$C$34,Supuestos!$C$33,Supuestos!$C$35)) -> 220000 | J21: =IF(J14<=Supuestos!$C$32,Supuestos!$C$31,IF(J14<=Supuestos!$C$34,Supuestos!$C$33,Supuestos!$C$35)) -> 220000 | ... BJ21: =IF(BJ14<=Supuestos!$C$32,Supuestos!$C$31,IF(BJ14<=Supuestos!$C$34,Supuestos!$C$33,Supuestos!$C$35)) -> 450000
A22: Total costos de operación del servicio | B22: COP | C22: =SUM(C19:C21) -> 232230.11 | D22: =SUM(D19:D21) -> 238352.5 | E22: =SUM(E19:E21) -> 250582.61 | F22: =SUM(F19:F21) -> 262827.39 | G22: =SUM(G19:G21) -> 275057.5 | H22: =SUM(H19:H21) -> 287287.61 | I22: =SUM(I19:I21) -> 299532.39 | J22: =SUM(J19:J21) -> 317884.89 | ... BJ22: =SUM(BJ19:BJ21) -> 2234606.3
A23: Margen bruto | B23: COP | C23: =C18-C22 -> -32809.906 | D23: =D18-D22 -> 60897.5 | E23: =E18-E22 -> 248087.59 | F23: =F18-F22 -> 435502.41 | G23: =G18-G22 -> 622692.5 | H23: =H18-H22 -> 809882.59 | I23: =I18-I22 -> 997297.41 | J23: =J18-J22 -> 1278194.9 | ... BJ23: =BJ18-BJ22 -> 26864613
A25: Carga de trabajo y equipo
A26: Horas de soporte | B26: horas | C26: =C14*Supuestos!$C$58/60 -> 1.666 | D26: =D14*Supuestos!$C$58/60 -> 2.5 | E26: =E14*Supuestos!$C$58/60 -> 4.166 | F26: =F14*Supuestos!$C$58/60 -> 5.834 | G26: =G14*Supuestos!$C$58/60 -> 7.5 | H26: =H14*Supuestos!$C$58/60 -> 9.166 | I26: =I14*Supuestos!$C$58/60 -> 10.834 | J26: =J14*Supuestos!$C$58/60 -> 13.334 | ... BJ26: =BJ14*Supuestos!$C$58/60 -> 200
A27: Horas de incorporación de clientes nuevos | B27: horas | C27: =C13*Supuestos!$C$59 -> 8.4966 | D27: =D13*Supuestos!$C$59 -> 4.67823 | E27: =E13*Supuestos!$C$59 -> 9.1341 | F27: =F13*Supuestos!$C$59 -> 9.56913 | G27: =G13*Supuestos!$C$59 -> 9.98427 | H27: =H13*Supuestos!$C$59 -> 10.4091 | I27: =I13*Supuestos!$C$59 -> 10.84413 | J27: =J13*Supuestos!$C$59 -> 15.51267 | ... BJ27: =BJ13*Supuestos!$C$59 -> 71.1875
A28: Horas de ventas | B28: horas | C28: =C13*Supuestos!$C$60 -> 19.992 | D28: =D13*Supuestos!$C$60 -> 11.0076 | E28: =E13*Supuestos!$C$60 -> 21.492 | F28: =F13*Supuestos!$C$60 -> 22.5156 | G28: =G13*Supuestos!$C$60 -> 23.4924 | H28: =H13*Supuestos!$C$60 -> 24.492 | I28: =I13*Supuestos!$C$60 -> 25.5156 | J28: =J13*Supuestos!$C$60 -> 36.5004 | ... BJ28: =BJ13*Supuestos!$C$60 -> 167.5
A29: Horas de desarrollo y mantenimiento | B29: horas | C29: =Supuestos!$C$61+C14/100*Supuestos!$C$62 -> 80.2499 | D29: =Supuestos!$C$61+D14/100*Supuestos!$C$62 -> 80.375 | E29: =Supuestos!$C$61+E14/100*Supuestos!$C$62 -> 80.6249 | F29: =Supuestos!$C$61+F14/100*Supuestos!$C$62 -> 80.8751 | G29: =Supuestos!$C$61+G14/100*Supuestos!$C$62 -> 81.125 | H29: =Supuestos!$C$61+H14/100*Supuestos!$C$62 -> 81.3749 | I29: =Supuestos!$C$61+I14/100*Supuestos!$C$62 -> 81.6251 | J29: =Supuestos!$C$61+J14/100*Supuestos!$C$62 -> 82.0001 | ... BJ29: =Supuestos!$C$61+BJ14/100*Supuestos!$C$62 -> 110
A30: Horas requeridas | B30: horas | C30: =SUM(C26:C29) -> 110.4045 | D30: =SUM(D26:D29) -> 98.56083 | E30: =SUM(E26:E29) -> 115.417 | F30: =SUM(F26:F29) -> 118.79383 | G30: =SUM(G26:G29) -> 122.10167 | H30: =SUM(H26:H29) -> 125.442 | I30: =SUM(I26:I29) -> 128.81883 | J30: =SUM(J26:J29) -> 147.34717 | ... BJ30: =SUM(BJ26:BJ29) -> 548.6875
A31: Capacidad de los fundadores | B31: horas | C31: =Supuestos!$C$51*IF(C6=1,Supuestos!$C$54,IF(C6=2,Supuestos!$C$55,Supuestos!$C$56)) -> 240 | D31: =Supuestos!$C$51*IF(D6=1,Supuestos!$C$54,IF(D6=2,Supuestos!$C$55,Supuestos!$C$56)) -> 240 | E31: =Supuestos!$C$51*IF(E6=1,Supuestos!$C$54,IF(E6=2,Supuestos!$C$55,Supuestos!$C$56)) -> 240 | F31: =Supuestos!$C$51*IF(F6=1,Supuestos!$C$54,IF(F6=2,Supuestos!$C$55,Supuestos!$C$56)) -> 240 | G31: =Supuestos!$C$51*IF(G6=1,Supuestos!$C$54,IF(G6=2,Supuestos!$C$55,Supuestos!$C$56)) -> 240 | H31: =Supuestos!$C$51*IF(H6=1,Supuestos!$C$54,IF(H6=2,Supuestos!$C$55,Supuestos!$C$56)) -> 240 | I31: =Supuestos!$C$51*IF(I6=1,Supuestos!$C$54,IF(I6=2,Supuestos!$C$55,Supuestos!$C$56)) -> 240 | J31: =Supuestos!$C$51*IF(J6=1,Supuestos!$C$54,IF(J6=2,Supuestos!$C$55,Supuestos!$C$56)) -> 240 | ... BJ31: =Supuestos!$C$51*IF(BJ6=1,Supuestos!$C$54,IF(BJ6=2,Supuestos!$C$55,Supuestos!$C$56)) -> 480
A32: Colaboradores contratados | B32: personas | C32: =IF(Supuestos!$C$8=1,MAX(0,ROUNDUP((C30-C31)/Supuestos!$C$57,0)),IF(C5=1,1,IF(C6=1,2,IF(C6=2,3,IF(C6=3,4,5))))) -> 0 | D32: =IF(Supuestos!$C$8=1,MAX(0,ROUNDUP((D30-D31)/Supuestos!$C$57,0)),IF(D5=1,1,IF(D6=1,2,IF(D6=2,3,IF(D6=3,4,5))))) -> 0 | E32: =IF(Supuestos!$C$8=1,MAX(0,ROUNDUP((E30-E31)/Supuestos!$C$57,0)),IF(E5=1,1,IF(E6=1,2,IF(E6=2,3,IF(E6=3,4,5))))) -> 0 | F32: =IF(Supuestos!$C$8=1,MAX(0,ROUNDUP((F30-F31)/Supuestos!$C$57,0)),IF(F5=1,1,IF(F6=1,2,IF(F6=2,3,IF(F6=3,4,5))))) -> 0 | G32: =IF(Supuestos!$C$8=1,MAX(0,ROUNDUP((G30-G31)/Supuestos!$C$57,0)),IF(G5=1,1,IF(G6=1,2,IF(G6=2,3,IF(G6=3,4,5))))) -> 0 | H32: =IF(Supuestos!$C$8=1,MAX(0,ROUNDUP((H30-H31)/Supuestos!$C$57,0)),IF(H5=1,1,IF(H6=1,2,IF(H6=2,3,IF(H6=3,4,5))))) -> 0 | I32: =IF(Supuestos!$C$8=1,MAX(0,ROUNDUP((I30-I31)/Supuestos!$C$57,0)),IF(I5=1,1,IF(I6=1,2,IF(I6=2,3,IF(I6=3,4,5))))) -> 0 | J32: =IF(Supuestos!$C$8=1,MAX(0,ROUNDUP((J30-J31)/Supuestos!$C$57,0)),IF(J5=1,1,IF(J6=1,2,IF(J6=2,3,IF(J6=3,4,5))))) -> 0 | ... BJ32: =IF(Supuestos!$C$8=1,MAX(0,ROUNDUP((BJ30-BJ31)/Supuestos!$C$57,0)),IF(BJ5=1,1,IF(BJ6=1,2,IF(BJ6=2,3,IF(BJ6=3,4,5))))) -> 1
A33: Costo total mensual por colaborador | B33: COP | C33: =Supuestos!$C$50*(1+Supuestos!$C$39)^(C6-1)*(1+Supuestos!$C$48)+IF(Supuestos!$C$50*(1+Supuestos!$C$39)^(C6-1)<=2*Supuestos!$C$37*(1+Supuestos!$C$39)^(C6-1),Supuestos!$C$38*(1+Supuestos!$C$39)^(C6-1)*(1+Supuestos!$C$49),0) -> 3060125.2 | D33: =Supuestos!$C$50*(1+Supuestos!$C$39)^(D6-1)*(1+Supuestos!$C$48)+IF(Supuestos!$C$50*(1+Supuestos!$C$39)^(D6-1)<=2*Supuestos!$C$37*(1+Supuestos!$C$39)^(D6-1),Supuestos!$C$38*(1+Supuestos!$C$39)^(D6-1)*(1+Supuestos!$C$49),0) -> 3060125.2 | E33: =Supuestos!$C$50*(1+Supuestos!$C$39)^(E6-1)*(1+Supuestos!$C$48)+IF(Supuestos!$C$50*(1+Supuestos!$C$39)^(E6-1)<=2*Supuestos!$C$37*(1+Supuestos!$C$39)^(E6-1),Supuestos!$C$38*(1+Supuestos!$C$39)^(E6-1)*(1+Supuestos!$C$49),0) -> 3060125.2 | F33: =Supuestos!$C$50*(1+Supuestos!$C$39)^(F6-1)*(1+Supuestos!$C$48)+IF(Supuestos!$C$50*(1+Supuestos!$C$39)^(F6-1)<=2*Supuestos!$C$37*(1+Supuestos!$C$39)^(F6-1),Supuestos!$C$38*(1+Supuestos!$C$39)^(F6-1)*(1+Supuestos!$C$49),0) -> 3060125.2 | G33: =Supuestos!$C$50*(1+Supuestos!$C$39)^(G6-1)*(1+Supuestos!$C$48)+IF(Supuestos!$C$50*(1+Supuestos!$C$39)^(G6-1)<=2*Supuestos!$C$37*(1+Supuestos!$C$39)^(G6-1),Supuestos!$C$38*(1+Supuestos!$C$39)^(G6-1)*(1+Supuestos!$C$49),0) -> 3060125.2 | H33: =Supuestos!$C$50*(1+Supuestos!$C$39)^(H6-1)*(1+Supuestos!$C$48)+IF(Supuestos!$C$50*(1+Supuestos!$C$39)^(H6-1)<=2*Supuestos!$C$37*(1+Supuestos!$C$39)^(H6-1),Supuestos!$C$38*(1+Supuestos!$C$39)^(H6-1)*(1+Supuestos!$C$49),0) -> 3060125.2 | I33: =Supuestos!$C$50*(1+Supuestos!$C$39)^(I6-1)*(1+Supuestos!$C$48)+IF(Supuestos!$C$50*(1+Supuestos!$C$39)^(I6-1)<=2*Supuestos!$C$37*(1+Supuestos!$C$39)^(I6-1),Supuestos!$C$38*(1+Supuestos!$C$39)^(I6-1)*(1+Supuestos!$C$49),0) -> 3060125.2 | J33: =Supuestos!$C$50*(1+Supuestos!$C$39)^(J6-1)*(1+Supuestos!$C$48)+IF(Supuestos!$C$50*(1+Supuestos!$C$39)^(J6-1)<=2*Supuestos!$C$37*(1+Supuestos!$C$39)^(J6-1),Supuestos!$C$38*(1+Supuestos!$C$39)^(J6-1)*(1+Supuestos!$C$49),0) -> 3060125.2 | ... BJ33: =Supuestos!$C$50*(1+Supuestos!$C$39)^(BJ6-1)*(1+Supuestos!$C$48)+IF(Supuestos!$C$50*(1+Supuestos!$C$39)^(BJ6-1)<=2*Supuestos!$C$37*(1+Supuestos!$C$39)^(BJ6-1),Supuestos!$C$38*(1+Supuestos!$C$39)^(BJ6-1)*(1+Supuestos!$C$49),0) -> 3719601.3
A34: Nómina de colaboradores | B34: COP | C34: =C32*C33 -> 0 | D34: =D32*D33 -> 0 | E34: =E32*E33 -> 0 | F34: =F32*F33 -> 0 | G34: =G32*G33 -> 0 | H34: =H32*H33 -> 0 | I34: =I32*I33 -> 0 | J34: =J32*J33 -> 0 | ... BJ34: =BJ32*BJ33 -> 3719601.3
A35: Fundadores con salario | B35: personas | C35: =IF(C5>=INDEX(Supuestos!$C$18:$E$18,1,$B$2),Supuestos!$C$51,0) -> 0 | D35: =IF(D5>=INDEX(Supuestos!$C$18:$E$18,1,$B$2),Supuestos!$C$51,0) -> 0 | E35: =IF(E5>=INDEX(Supuestos!$C$18:$E$18,1,$B$2),Supuestos!$C$51,0) -> 0 | F35: =IF(F5>=INDEX(Supuestos!$C$18:$E$18,1,$B$2),Supuestos!$C$51,0) -> 0 | G35: =IF(G5>=INDEX(Supuestos!$C$18:$E$18,1,$B$2),Supuestos!$C$51,0) -> 0 | H35: =IF(H5>=INDEX(Supuestos!$C$18:$E$18,1,$B$2),Supuestos!$C$51,0) -> 0 | I35: =IF(I5>=INDEX(Supuestos!$C$18:$E$18,1,$B$2),Supuestos!$C$51,0) -> 0 | J35: =IF(J5>=INDEX(Supuestos!$C$18:$E$18,1,$B$2),Supuestos!$C$51,0) -> 0 | ... BJ35: =IF(BJ5>=INDEX(Supuestos!$C$18:$E$18,1,$B$2),Supuestos!$C$51,0) -> 3
A36: Costo total mensual por fundador | B36: COP | C36: =Supuestos!$C$52*(1+Supuestos!$C$39)^(C6-1)*(1+Supuestos!$C$48)+IF(Supuestos!$C$52*(1+Supuestos!$C$39)^(C6-1)<=2*Supuestos!$C$37*(1+Supuestos!$C$39)^(C6-1),Supuestos!$C$38*(1+Supuestos!$C$39)^(C6-1)*(1+Supuestos!$C$49),0) -> 4443645.2 | D36: =Supuestos!$C$52*(1+Supuestos!$C$39)^(D6-1)*(1+Supuestos!$C$48)+IF(Supuestos!$C$52*(1+Supuestos!$C$39)^(D6-1)<=2*Supuestos!$C$37*(1+Supuestos!$C$39)^(D6-1),Supuestos!$C$38*(1+Supuestos!$C$39)^(D6-1)*(1+Supuestos!$C$49),0) -> 4443645.2 | E36: =Supuestos!$C$52*(1+Supuestos!$C$39)^(E6-1)*(1+Supuestos!$C$48)+IF(Supuestos!$C$52*(1+Supuestos!$C$39)^(E6-1)<=2*Supuestos!$C$37*(1+Supuestos!$C$39)^(E6-1),Supuestos!$C$38*(1+Supuestos!$C$39)^(E6-1)*(1+Supuestos!$C$49),0) -> 4443645.2 | F36: =Supuestos!$C$52*(1+Supuestos!$C$39)^(F6-1)*(1+Supuestos!$C$48)+IF(Supuestos!$C$52*(1+Supuestos!$C$39)^(F6-1)<=2*Supuestos!$C$37*(1+Supuestos!$C$39)^(F6-1),Supuestos!$C$38*(1+Supuestos!$C$39)^(F6-1)*(1+Supuestos!$C$49),0) -> 4443645.2 | G36: =Supuestos!$C$52*(1+Supuestos!$C$39)^(G6-1)*(1+Supuestos!$C$48)+IF(Supuestos!$C$52*(1+Supuestos!$C$39)^(G6-1)<=2*Supuestos!$C$37*(1+Supuestos!$C$39)^(G6-1),Supuestos!$C$38*(1+Supuestos!$C$39)^(G6-1)*(1+Supuestos!$C$49),0) -> 4443645.2 | H36: =Supuestos!$C$52*(1+Supuestos!$C$39)^(H6-1)*(1+Supuestos!$C$48)+IF(Supuestos!$C$52*(1+Supuestos!$C$39)^(H6-1)<=2*Supuestos!$C$37*(1+Supuestos!$C$39)^(H6-1),Supuestos!$C$38*(1+Supuestos!$C$39)^(H6-1)*(1+Supuestos!$C$49),0) -> 4443645.2 | I36: =Supuestos!$C$52*(1+Supuestos!$C$39)^(I6-1)*(1+Supuestos!$C$48)+IF(Supuestos!$C$52*(1+Supuestos!$C$39)^(I6-1)<=2*Supuestos!$C$37*(1+Supuestos!$C$39)^(I6-1),Supuestos!$C$38*(1+Supuestos!$C$39)^(I6-1)*(1+Supuestos!$C$49),0) -> 4443645.2 | J36: =Supuestos!$C$52*(1+Supuestos!$C$39)^(J6-1)*(1+Supuestos!$C$48)+IF(Supuestos!$C$52*(1+Supuestos!$C$39)^(J6-1)<=2*Supuestos!$C$37*(1+Supuestos!$C$39)^(J6-1),Supuestos!$C$38*(1+Supuestos!$C$39)^(J6-1)*(1+Supuestos!$C$49),0) -> 4443645.2 | ... BJ36: =Supuestos!$C$52*(1+Supuestos!$C$39)^(BJ6-1)*(1+Supuestos!$C$48)+IF(Supuestos!$C$52*(1+Supuestos!$C$39)^(BJ6-1)<=2*Supuestos!$C$37*(1+Supuestos!$C$39)^(BJ6-1),Supuestos!$C$38*(1+Supuestos!$C$39)^(BJ6-1)*(1+Supuestos!$C$49),0) -> 5401278.5
A37: Nómina de fundadores | B37: COP | C37: =C35*C36 -> 0 | D37: =D35*D36 -> 0 | E37: =E35*E36 -> 0 | F37: =F35*F36 -> 0 | G37: =G35*G36 -> 0 | H37: =H35*H36 -> 0 | I37: =I35*I36 -> 0 | J37: =J35*J36 -> 0 | ... BJ37: =BJ35*BJ36 -> 16203835
A38: Personas en el equipo (fundadores + colaboradores) | B38: personas | C38: =Supuestos!$C$51+C32 -> 3 | D38: =Supuestos!$C$51+D32 -> 3 | E38: =Supuestos!$C$51+E32 -> 3 | F38: =Supuestos!$C$51+F32 -> 3 | G38: =Supuestos!$C$51+G32 -> 3 | H38: =Supuestos!$C$51+H32 -> 3 | I38: =Supuestos!$C$51+I32 -> 3 | J38: =Supuestos!$C$51+J32 -> 3 | ... BJ38: =Supuestos!$C$51+BJ32 -> 4
A40: Gastos operativos
A41: Nómina total | B41: COP | C41: =C34+C37 -> 0 | D41: =D34+D37 -> 0 | E41: =E34+E37 -> 0 | F41: =F34+F37 -> 0 | G41: =G34+G37 -> 0 | H41: =H34+H37 -> 0 | I41: =I34+I37 -> 0 | J41: =J34+J37 -> 0 | ... BJ41: =BJ34+BJ37 -> 19923437
A42: Marketing y adquisición de clientes | B42: COP | C42: =C13*INDEX(Supuestos!$C$17:$E$17,1,$B$2)*(1+Supuestos!$C$39)^(C6-1) -> 499800 | D42: =D13*INDEX(Supuestos!$C$17:$E$17,1,$B$2)*(1+Supuestos!$C$39)^(D6-1) -> 275190 | E42: =E13*INDEX(Supuestos!$C$17:$E$17,1,$B$2)*(1+Supuestos!$C$39)^(E6-1) -> 537300 | F42: =F13*INDEX(Supuestos!$C$17:$E$17,1,$B$2)*(1+Supuestos!$C$39)^(F6-1) -> 562890 | G42: =G13*INDEX(Supuestos!$C$17:$E$17,1,$B$2)*(1+Supuestos!$C$39)^(G6-1) -> 587310 | H42: =H13*INDEX(Supuestos!$C$17:$E$17,1,$B$2)*(1+Supuestos!$C$39)^(H6-1) -> 612300 | I42: =I13*INDEX(Supuestos!$C$17:$E$17,1,$B$2)*(1+Supuestos!$C$39)^(I6-1) -> 637890 | J42: =J13*INDEX(Supuestos!$C$17:$E$17,1,$B$2)*(1+Supuestos!$C$39)^(J6-1) -> 912510 | ... BJ42: =BJ13*INDEX(Supuestos!$C$17:$E$17,1,$B$2)*(1+Supuestos!$C$39)^(BJ6-1) -> 5089932.4
A43: Arriendo de coworking | B43: COP | C43: =IF(C5>=Supuestos!$C$65,Supuestos!$C$64*(1+Supuestos!$C$39)^(C6-1),0) -> 0 | D43: =IF(D5>=Supuestos!$C$65,Supuestos!$C$64*(1+Supuestos!$C$39)^(D6-1),0) -> 0 | E43: =IF(E5>=Supuestos!$C$65,Supuestos!$C$64*(1+Supuestos!$C$39)^(E6-1),0) -> 0 | F43: =IF(F5>=Supuestos!$C$65,Supuestos!$C$64*(1+Supuestos!$C$39)^(F6-1),0) -> 0 | G43: =IF(G5>=Supuestos!$C$65,Supuestos!$C$64*(1+Supuestos!$C$39)^(G6-1),0) -> 0 | H43: =IF(H5>=Supuestos!$C$65,Supuestos!$C$64*(1+Supuestos!$C$39)^(H6-1),0) -> 0 | I43: =IF(I5>=Supuestos!$C$65,Supuestos!$C$64*(1+Supuestos!$C$39)^(I6-1),0) -> 0 | J43: =IF(J5>=Supuestos!$C$65,Supuestos!$C$64*(1+Supuestos!$C$39)^(J6-1),0) -> 0 | ... BJ43: =IF(BJ5>=Supuestos!$C$65,Supuestos!$C$64*(1+Supuestos!$C$39)^(BJ6-1),0) -> 607753.12
A44: Gastos administrativos y legales | B44: COP | C44: =IF(C6=1,Supuestos!$C$66,Supuestos!$C$67*(1+Supuestos!$C$39)^(C6-2)) -> 200000 | D44: =IF(D6=1,Supuestos!$C$66,Supuestos!$C$67*(1+Supuestos!$C$39)^(D6-2)) -> 200000 | E44: =IF(E6=1,Supuestos!$C$66,Supuestos!$C$67*(1+Supuestos!$C$39)^(E6-2)) -> 200000 | F44: =IF(F6=1,Supuestos!$C$66,Supuestos!$C$67*(1+Supuestos!$C$39)^(F6-2)) -> 200000 | G44: =IF(G6=1,Supuestos!$C$66,Supuestos!$C$67*(1+Supuestos!$C$39)^(G6-2)) -> 200000 | H44: =IF(H6=1,Supuestos!$C$66,Supuestos!$C$67*(1+Supuestos!$C$39)^(H6-2)) -> 200000 | I44: =IF(I6=1,Supuestos!$C$66,Supuestos!$C$67*(1+Supuestos!$C$39)^(I6-2)) -> 200000 | J44: =IF(J6=1,Supuestos!$C$66,Supuestos!$C$67*(1+Supuestos!$C$39)^(J6-2)) -> 200000 | ... BJ44: =IF(BJ6=1,Supuestos!$C$66,Supuestos!$C$67*(1+Supuestos!$C$39)^(BJ6-2)) -> 463050
A45: Software, herramientas, dominio y SSL | B45: COP | C45: =(Supuestos!$C$68+Supuestos!$C$69)*(1+Supuestos!$C$39)^(C6-1) -> 110000 | D45: =(Supuestos!$C$68+Supuestos!$C$69)*(1+Supuestos!$C$39)^(D6-1) -> 110000 | E45: =(Supuestos!$C$68+Supuestos!$C$69)*(1+Supuestos!$C$39)^(E6-1) -> 110000 | F45: =(Supuestos!$C$68+Supuestos!$C$69)*(1+Supuestos!$C$39)^(F6-1) -> 110000 | G45: =(Supuestos!$C$68+Supuestos!$C$69)*(1+Supuestos!$C$39)^(G6-1) -> 110000 | H45: =(Supuestos!$C$68+Supuestos!$C$69)*(1+Supuestos!$C$39)^(H6-1) -> 110000 | I45: =(Supuestos!$C$68+Supuestos!$C$69)*(1+Supuestos!$C$39)^(I6-1) -> 110000 | J45: =(Supuestos!$C$68+Supuestos!$C$69)*(1+Supuestos!$C$39)^(J6-1) -> 110000 | ... BJ45: =(Supuestos!$C$68+Supuestos!$C$69)*(1+Supuestos!$C$39)^(BJ6-1) -> 133705.69
...

Sheet Base
A1: Escenario Base — proyección mensual (60 meses) y anual
A2: Índice del escenario | B2: 2
A3: Todo en esta hoja es fórmula. Para cambiar resultados, edite la hoja Supuestos.
A5: Mes | C5: 1 | D5: 2 | E5: 3 | F5: 4 | G5: 5 | H5: 6 | I5: 7 | J5: 8 | K5: 9 | L5: 10 | M5: 11 | N5: 12 | O5: 13 | P5: 14 | Q5: 15 | R5: 16 | S5: 17 | T5: 18 | U5: 19 | V5: 20 | W5: 21 | X5: 22 | Y5: 23 | Z5: 24 | AA5: 25 | AB5: 26 | AC5: 27 | AD5: 28 | AE5: 29 | AF5: 30 | AG5: 31 | AH5: 32 | AI5: 33 | AJ5: 34 | AK5: 35 | AL5: 36 | AM5: 37 | AN5: 38 | AO5: 39 | AP5: 40 | AQ5: 41 | AR5: 42 | AS5: 43 | AT5: 44 | AU5: 45 | AV5: 46 | AW5: 47 | AX5: 48 | AY5: 49 | AZ5: 50 | BA5: 51 | BB5: 52 | BC5: 53 | BD5: 54 | BE5: 55 | BF5: 56 | BG5: 57 | BH5: 58 | BI5: 59 | BJ5: 60
A6: Año | C6: =ROUNDUP(C5/12,0) -> 1 | D6: =ROUNDUP(D5/12,0) -> 1 | E6: =ROUNDUP(E5/12,0) -> 1 | F6: =ROUNDUP(F5/12,0) -> 1 | G6: =ROUNDUP(G5/12,0) -> 1 | H6: =ROUNDUP(H5/12,0) -> 1 | I6: =ROUNDUP(I5/12,0) -> 1 | J6: =ROUNDUP(J5/12,0) -> 1 | ... BJ6: =ROUNDUP(BJ5/12,0) -> 5
A7: Mes del año | C7: =C5-(C6-1)*12 -> 1 | D7: =D5-(D6-1)*12 -> 2 | E7: =E5-(E6-1)*12 -> 3 | F7: =F5-(F6-1)*12 -> 4 | G7: =G5-(G6-1)*12 -> 5 | H7: =H5-(H6-1)*12 -> 6 | I7: =I5-(I6-1)*12 -> 7 | J7: =J5-(J6-1)*12 -> 8 | ... BJ7: =BJ5-(BJ6-1)*12 -> 12
A9: Clientes
A10: Meta de clientes activos al cierre del mes | B10: clientes | C10: =IF(C6=1,INDEX(Supuestos!$C$22:$N$22,1,C7)*INDEX(Supuestos!$C$11:$E$11,1,$B$2),IF(C6=2,INDEX(Supuestos!$C$11:$E$11,1,$B$2),IF(C6=3,INDEX(Supuestos!$C$12:$E$12,1,$B$2),IF(C6=4,INDEX(Supuestos!$C$13:$E$13,1,$B$2),INDEX(Supuestos!$C$14:$E$14,1,$B$2))))+(IF(C6=2,INDEX(Supuestos!$C$12:$E$12,1,$B$2),IF(C6=3,INDEX(Supuestos!$C$13:$E$13,1,$B$2),IF(C6=4,INDEX(Supuestos!$C$14:$E$14,1,$B$2),INDEX(Supuestos!$C$15:$E$15,1,$B$2))))-IF(C6=2,INDEX(Supuestos!$C$11:$E$11,1,$B$2),IF(C6=3,INDEX(Supuestos!$C$12:$E$12,1,$B$2),IF(C6=4,INDEX(Supuestos!$C$13:$E$13,1,$B$2),INDEX(Supuestos!$C$14:$E$14,1,$B$2)))))*C7/12) -> 9.996 | D10: =IF(D6=1,INDEX(Supuestos!$C$22:$N$22,1,D7)*INDEX(Supuestos!$C$11:$E$11,1,$B$2),IF(D6=2,INDEX(Supuestos!$C$11:$E$11,1,$B$2),IF(D6=3,INDEX(Supuestos!$C$12:$E$12,1,$B$2),IF(D6=4,INDEX(Supuestos!$C$13:$E$13,1,$B$2),INDEX(Supuestos!$C$14:$E$14,1,$B$2))))+(IF(D6=2,INDEX(Supuestos!$C$12:$E$12,1,$B$2),IF(D6=3,INDEX(Supuestos!$C$13:$E$13,1,$B$2),IF(D6=4,INDEX(Supuestos!$C$14:$E$14,1,$B$2),INDEX(Supuestos!$C$15:$E$15,1,$B$2))))-IF(D6=2,INDEX(Supuestos!$C$11:$E$11,1,$B$2),IF(D6=3,INDEX(Supuestos!$C$12:$E$12,1,$B$2),IF(D6=4,INDEX(Supuestos!$C$13:$E$13,1,$B$2),INDEX(Supuestos!$C$14:$E$14,1,$B$2)))))*D7/12) -> 15 | E10: =IF(E6=1,INDEX(Supuestos!$C$22:$N$22,1,E7)*INDEX(Supuestos!$C$11:$E$11,1,$B$2),IF(E6=2,INDEX(Supuestos!$C$11:$E$11,1,$B$2),IF(E6=3,INDEX(Supuestos!$C$12:$E$12,1,$B$2),IF(E6=4,INDEX(Supuestos!$C$13:$E$13,1,$B$2),INDEX(Supuestos!$C$14:$E$14,1,$B$2))))+(IF(E6=2,INDEX(Supuestos!$C$12:$E$12,1,$B$2),IF(E6=3,INDEX(Supuestos!$C$13:$E$13,1,$B$2),IF(E6=4,INDEX(Supuestos!$C$14:$E$14,1,$B$2),INDEX(Supuestos!$C$15:$E$15,1,$B$2))))-IF(E6=2,INDEX(Supuestos!$C$11:$E$11,1,$B$2),IF(E6=3,INDEX(Supuestos!$C$12:$E$12,1,$B$2),IF(E6=4,INDEX(Supuestos!$C$13:$E$13,1,$B$2),INDEX(Supuestos!$C$14:$E$14,1,$B$2)))))*E7/12) -> 24.996 | F10: =IF(F6=1,INDEX(Supuestos!$C$22:$N$22,1,F7)*INDEX(Supuestos!$C$11:$E$11,1,$B$2),IF(F6=2,INDEX(Supuestos!$C$11:$E$11,1,$B$2),IF(F6=3,INDEX(Supuestos!$C$12:$E$12,1,$B$2),IF(F6=4,INDEX(Supuestos!$C$13:$E$13,1,$B$2),INDEX(Supuestos!$C$14:$E$14,1,$B$2))))+(IF(F6=2,INDEX(Supuestos!$C$12:$E$12,1,$B$2),IF(F6=3,INDEX(Supuestos!$C$13:$E$13,1,$B$2),IF(F6=4,INDEX(Supuestos!$C$14:$E$14,1,$B$2),INDEX(Supuestos!$C$15:$E$15,1,$B$2))))-IF(F6=2,INDEX(Supuestos!$C$11:$E$11,1,$B$2),IF(F6=3,INDEX(Supuestos!$C$12:$E$12,1,$B$2),IF(F6=4,INDEX(Supuestos!$C$13:$E$13,1,$B$2),INDEX(Supuestos!$C$14:$E$14,1,$B$2)))))*F7/12) -> 35.004 | G10: =IF(G6=1,INDEX(Supuestos!$C$22:$N$22,1,G7)*INDEX(Supuestos!$C$11:$E$11,1,$B$2),IF(G6=2,INDEX(Supuestos!$C$11:$E$11,1,$B$2),IF(G6=3,INDEX(Supuestos!$C$12:$E$12,1,$B$2),IF(G6=4,INDEX(Supuestos!$C$13:$E$13,1,$B$2),INDEX(Supuestos!$C$14:$E$14,1,$B$2))))+(IF(G6=2,INDEX(Supuestos!$C$12:$E$12,1,$B$2),IF(G6=3,INDEX(Supuestos!$C$13:$E$13,1,$B$2),IF(G6=4,INDEX(Supuestos!$C$14:$E$14,1,$B$2),INDEX(Supuestos!$C$15:$E$15,1,$B$2))))-IF(G6=2,INDEX(Supuestos!$C$11:$E$11,1,$B$2),IF(G6=3,INDEX(Supuestos!$C$12:$E$12,1,$B$2),IF(G6=4,INDEX(Supuestos!$C$13:$E$13,1,$B$2),INDEX(Supuestos!$C$14:$E$14,1,$B$2)))))*G7/12) -> 45 | H10: =IF(H6=1,INDEX(Supuestos!$C$22:$N$22,1,H7)*INDEX(Supuestos!$C$11:$E$11,1,$B$2),IF(H6=2,INDEX(Supuestos!$C$11:$E$11,1,$B$2),IF(H6=3,INDEX(Supuestos!$C$12:$E$12,1,$B$2),IF(H6=4,INDEX(Supuestos!$C$13:$E$13,1,$B$2),INDEX(Supuestos!$C$14:$E$14,1,$B$2))))+(IF(H6=2,INDEX(Supuestos!$C$12:$E$12,1,$B$2),IF(H6=3,INDEX(Supuestos!$C$13:$E$13,1,$B$2),IF(H6=4,INDEX(Supuestos!$C$14:$E$14,1,$B$2),INDEX(Supuestos!$C$15:$E$15,1,$B$2))))-IF(H6=2,INDEX(Supuestos!$C$11:$E$11,1,$B$2),IF(H6=3,INDEX(Supuestos!$C$12:$E$12,1,$B$2),IF(H6=4,INDEX(Supuestos!$C$13:$E$13,1,$B$2),INDEX(Supuestos!$C$14:$E$14,1,$B$2)))))*H7/12) -> 54.996 | I10: =IF(I6=1,INDEX(Supuestos!$C$22:$N$22,1,I7)*INDEX(Supuestos!$C$11:$E$11,1,$B$2),IF(I6=2,INDEX(Supuestos!$C$11:$E$11,1,$B$2),IF(I6=3,INDEX(Supuestos!$C$12:$E$12,1,$B$2),IF(I6=4,INDEX(Supuestos!$C$13:$E$13,1,$B$2),INDEX(Supuestos!$C$14:$E$14,1,$B$2))))+(IF(I6=2,INDEX(Supuestos!$C$12:$E$12,1,$B$2),IF(I6=3,INDEX(Supuestos!$C$13:$E$13,1,$B$2),IF(I6=4,INDEX(Supuestos!$C$14:$E$14,1,$B$2),INDEX(Supuestos!$C$15:$E$15,1,$B$2))))-IF(I6=2,INDEX(Supuestos!$C$11:$E$11,1,$B$2),IF(I6=3,INDEX(Supuestos!$C$12:$E$12,1,$B$2),IF(I6=4,INDEX(Supuestos!$C$13:$E$13,1,$B$2),INDEX(Supuestos!$C$14:$E$14,1,$B$2)))))*I7/12) -> 65.004 | J10: =IF(J6=1,INDEX(Supuestos!$C$22:$N$22,1,J7)*INDEX(Supuestos!$C$11:$E$11,1,$B$2),IF(J6=2,INDEX(Supuestos!$C$11:$E$11,1,$B$2),IF(J6=3,INDEX(Supuestos!$C$12:$E$12,1,$B$2),IF(J6=4,INDEX(Supuestos!$C$13:$E$13,1,$B$2),INDEX(Supuestos!$C$14:$E$14,1,$B$2))))+(IF(J6=2,INDEX(Supuestos!$C$12:$E$12,1,$B$2),IF(J6=3,INDEX(Supuestos!$C$13:$E$13,1,$B$2),IF(J6=4,INDEX(Supuestos!$C$14:$E$14,1,$B$2),INDEX(Supuestos!$C$15:$E$15,1,$B$2))))-IF(J6=2,INDEX(Supuestos!$C$11:$E$11,1,$B$2),IF(J6=3,INDEX(Supuestos!$C$12:$E$12,1,$B$2),IF(J6=4,INDEX(Supuestos!$C$13:$E$13,1,$B$2),INDEX(Supuestos!$C$14:$E$14,1,$B$2)))))*J7/12) -> 80.004 | ... BJ10: =IF(BJ6=1,INDEX(Supuestos!$C$22:$N$22,1,BJ7)*INDEX(Supuestos!$C$11:$E$11,1,$B$2),IF(BJ6=2,INDEX(Supuestos!$C$11:$E$11,1,$B$2),IF(BJ6=3,INDEX(Supuestos!$C$12:$E$12,1,$B$2),IF(BJ6=4,INDEX(Supuestos!$C$13:$E$13,1,$B$2),INDEX(Supuestos!$C$14:$E$14,1,$B$2))))+(IF(BJ6=2,INDEX(Supuestos!$C$12:$E$12,1,$B$2),IF(BJ6=3,INDEX(Supuestos!$C$13:$E$13,1,$B$2),IF(BJ6=4,INDEX(Supuestos!$C$14:$E$14,1,$B$2),INDEX(Supuestos!$C$15:$E$15,1,$B$2))))-IF(BJ6=2,INDEX(Supuestos!$C$11:$E$11,1,$B$2),IF(BJ6=3,INDEX(Supuestos!$C$12:$E$12,1,$B$2),IF(BJ6=4,INDEX(Supuestos!$C$13:$E$13,1,$B$2),INDEX(Supuestos!$C$14:$E$14,1,$B$2)))))*BJ7/12) -> 1200
A11: Clientes al inicio del mes | B11: clientes | C11: 0 | D11: =C14 -> 9.996 | E11: =D14 -> 15 | F11: =E14 -> 24.996 | G11: =F14 -> 35.004 | H11: =G14 -> 45 | I11: =H14 -> 54.996 | J11: =I14 -> 65.004 | K11: =J14 -> 80.004 | ... BJ11: =BI14 -> 1175
A12: Clientes que se retiran | B12: clientes | C12: =C11*INDEX(Supuestos!$C$16:$E$16,1,$B$2) -> 0 | D12: =D11*INDEX(Supuestos!$C$16:$E$16,1,$B$2) -> 0.29988 | E12: =E11*INDEX(Supuestos!$C$16:$E$16,1,$B$2) -> 0.45 | F12: =F11*INDEX(Supuestos!$C$16:$E$16,1,$B$2) -> 0.74988 | G12: =G11*INDEX(Supuestos!$C$16:$E$16,1,$B$2) -> 1.05012 | H12: =H11*INDEX(Supuestos!$C$16:$E$16,1,$B$2) -> 1.35 | I12: =I11*INDEX(Supuestos!$C$16:$E$16,1,$B$2) -> 1.64988 | J12: =J11*INDEX(Supuestos!$C$16:$E$16,1,$B$2) -> 1.95012 | ... BJ12: =BJ11*INDEX(Supuestos!$C$16:$E$16,1,$B$2) -> 35.25
A13: Clientes nuevos | B13: clientes | C13: =MAX(0,C10-(C11-C12)) -> 9.996 | D13: =MAX(0,D10-(D11-D12)) -> 5.30388 | E13: =MAX(0,E10-(E11-E12)) -> 10.446 | F13: =MAX(0,F10-(F11-F12)) -> 10.75788 | G13: =MAX(0,G10-(G11-G12)) -> 11.04612 | H13: =MAX(0,H10-(H11-H12)) -> 11.346 | I13: =MAX(0,I10-(I11-I12)) -> 11.65788 | J13: =MAX(0,J10-(J11-J12)) -> 16.95012 | ... BJ13: =MAX(0,BJ10-(BJ11-BJ12)) -> 60.25
A14: Clientes activos al cierre del mes | B14: clientes | C14: =C11-C12+C13 -> 9.996 | D14: =D11-D12+D13 -> 15 | E14: =E11-E12+E13 -> 24.996 | F14: =F11-F12+F13 -> 35.004 | G14: =G11-G12+G13 -> 45 | H14: =H11-H12+H13 -> 54.996 | I14: =I11-I12+I13 -> 65.004 | J14: =J11-J12+J13 -> 80.004 | ... BJ14: =BJ11-BJ12+BJ13 -> 1200
A16: Ingresos y costos variables
A17: Precio mensual por tienda | B17: COP | C17: =Supuestos!$C$26*(1+Supuestos!$C$27)^(C6-1) -> 39900 | D17: =Supuestos!$C$26*(1+Supuestos!$C$27)^(D6-1) -> 39900 | E17: =Supuestos!$C$26*(1+Supuestos!$C$27)^(E6-1) -> 39900 | F17: =Supuestos!$C$26*(1+Supuestos!$C$27)^(F6-1) -> 39900 | G17: =Supuestos!$C$26*(1+Supuestos!$C$27)^(G6-1) -> 39900 | H17: =Supuestos!$C$26*(1+Supuestos!$C$27)^(H6-1) -> 39900 | I17: =Supuestos!$C$26*(1+Supuestos!$C$27)^(I6-1) -> 39900 | J17: =Supuestos!$C$26*(1+Supuestos!$C$27)^(J6-1) -> 39900 | ... BJ17: =Supuestos!$C$26*(1+Supuestos!$C$27)^(BJ6-1) -> 48498.699
A18: Ingresos | B18: COP | C18: =C14*C17 -> 398840.4 | D18: =D14*D17 -> 598500 | E18: =E14*E17 -> 997340.4 | F18: =F14*F17 -> 1396659.6 | G18: =G14*G17 -> 1795500 | H18: =H14*H17 -> 2194340.4 | I18: =I14*I17 -> 2593659.6 | J18: =J14*J17 -> 3192159.6 | ... BJ18: =BJ14*BJ17 -> 58198439
A19: Costo de IA | B19: COP | C19: =C14*Supuestos!$C$29*(1+Supuestos!$C$39)^(C6-1) -> 12495 | D19: =D14*Supuestos!$C$29*(1+Supuestos!$C$39)^(D6-1) -> 18750 | E19: =E14*Supuestos!$C$29*(1+Supuestos!$C$39)^(E6-1) -> 31245 | F19: =F14*Supuestos!$C$29*(1+Supuestos!$C$39)^(F6-1) -> 43755 | G19: =G14*Supuestos!$C$29*(1+Supuestos!$C$39)^(G6-1) -> 56250 | H19: =H14*Supuestos!$C$29*(1+Supuestos!$C$39)^(H6-1) -> 68745 | I19: =I14*Supuestos!$C$29*(1+Supuestos!$C$39)^(I6-1) -> 81255 | J19: =J14*Supuestos!$C$29*(1+Supuestos!$C$39)^(J6-1) -> 100005 | ... BJ19: =BJ14*Supuestos!$C$29*(1+Supuestos!$C$39)^(BJ6-1) -> 1823259.4
A20: Comisión de pasarela de pagos | B20: COP | C20: =C18*Supuestos!$C$30 -> 11965.212 | D20: =D18*Supuestos!$C$30 -> 17955 | E20: =E18*Supuestos!$C$30 -> 29920.212 | F20: =F18*Supuestos!$C$30 -> 41899.788 | G20: =G18*Supuestos!$C$30 -> 53865 | H20: =H18*Supuestos!$C$30 -> 65830.212 | I20: =I18*Supuestos!$C$30 -> 77809.788 | J20: =J18*Supuestos!$C$30 -> 95764.788 | ... BJ20: =BJ18*Supuestos!$C$30 -> 1745953.2
A21: Infraestructura en la nube | B21: COP | C21: =IF(C14<=Supuestos!$C$32,Supuestos!$C$31,IF(C14<=Supuestos!$C$34,Supuestos!$C$33,Supuestos!$C$35)) -> 220000 | D21: =IF(D14<=Supuestos!$C$32,Supuestos!$C$31,IF(D14<=Supuestos!$C$34,Supuestos!$C$33,Supuestos!$C$35)) -> 220000 | E21: =IF(E14<=Supuestos!$C$32,Supuestos!$C$31,IF(E14<=Supuestos!$C$34,Supuestos!$C$33,Supuestos!$C$35)) -> 220000 | F21: =IF(F14<=Supuestos!$C$32,Supuestos!$C$31,IF(F14<=Supuestos!$C$34,Supuestos!$C$33,Supuestos!$C$35)) -> 220000 | G21: =IF(G14<=Supuestos!$C$32,Supuestos!$C$31,IF(G14<=Supuestos!$C$34,Supuestos!$C$33,Supuestos!$C$35)) -> 220000 | H21: =IF(H14<=Supuestos!$C$32,Supuestos!$C$31,IF(H14<=Supuestos!$C$34,Supuestos!$C$33,Supuestos!$C$35)) -> 220000 | I21: =IF(I14<=Supuestos!$C$32,Supuestos!$C$31,IF(I14<=Supuestos!$C$34,Supuestos!$C$33,Supuestos!$C$35)) -> 220000 | J21: =IF(J14<=Supuestos!$C$32,Supuestos!$C$31,IF(J14<=Supuestos!$C$34,Supuestos!$C$33,Supuestos!$C$35)) -> 220000 | ... BJ21: =IF(BJ14<=Supuestos!$C$32,Supuestos!$C$31,IF(BJ14<=Supuestos!$C$34,Supuestos!$C$33,Supuestos!$C$35)) -> 800000
A22: Total costos de operación del servicio | B22: COP | C22: =SUM(C19:C21) -> 244460.21 | D22: =SUM(D19:D21) -> 256705 | E22: =SUM(E19:E21) -> 281165.21 | F22: =SUM(F19:F21) -> 305654.79 | G22: =SUM(G19:G21) -> 330115 | H22: =SUM(H19:H21) -> 354575.21 | I22: =SUM(I19:I21) -> 379064.79 | J22: =SUM(J19:J21) -> 415769.79 | ... BJ22: =SUM(BJ19:BJ21) -> 4369212.6
A23: Margen bruto | B23: COP | C23: =C18-C22 -> 154380.19 | D23: =D18-D22 -> 341795 | E23: =E18-E22 -> 716175.19 | F23: =F18-F22 -> 1091004.8 | G23: =G18-G22 -> 1465385 | H23: =H18-H22 -> 1839765.2 | I23: =I18-I22 -> 2214594.8 | J23: =J18-J22 -> 2776389.8 | ... BJ23: =BJ18-BJ22 -> 53829227
A25: Carga de trabajo y equipo
A26: Horas de soporte | B26: horas | C26: =C14*Supuestos!$C$58/60 -> 3.332 | D26: =D14*Supuestos!$C$58/60 -> 5 | E26: =E14*Supuestos!$C$58/60 -> 8.332 | F26: =F14*Supuestos!$C$58/60 -> 11.668 | G26: =G14*Supuestos!$C$58/60 -> 15 | H26: =H14*Supuestos!$C$58/60 -> 18.332 | I26: =I14*Supuestos!$C$58/60 -> 21.668 | J26: =J14*Supuestos!$C$58/60 -> 26.668 | ... BJ26: =BJ14*Supuestos!$C$58/60 -> 400
A27: Horas de incorporación de clientes nuevos | B27: horas | C27: =C13*Supuestos!$C$59 -> 16.9932 | D27: =D13*Supuestos!$C$59 -> 9.016596 | E27: =E13*Supuestos!$C$59 -> 17.7582 | F27: =F13*Supuestos!$C$59 -> 18.288396 | G27: =G13*Supuestos!$C$59 -> 18.778404 | H27: =H13*Supuestos!$C$59 -> 19.2882 | I27: =I13*Supuestos!$C$59 -> 19.818396 | J27: =J13*Supuestos!$C$59 -> 28.815204 | ... BJ27: =BJ13*Supuestos!$C$59 -> 102.425
A28: Horas de ventas | B28: horas | C28: =C13*Supuestos!$C$60 -> 39.984 | D28: =D13*Supuestos!$C$60 -> 21.21552 | E28: =E13*Supuestos!$C$60 -> 41.784 | F28: =F13*Supuestos!$C$60 -> 43.03152 | G28: =G13*Supuestos!$C$60 -> 44.18448 | H28: =H13*Supuestos!$C$60 -> 45.384 | I28: =I13*Supuestos!$C$60 -> 46.63152 | J28: =J13*Supuestos!$C$60 -> 67.80048 | ... BJ28: =BJ13*Supuestos!$C$60 -> 241
A29: Horas de desarrollo y mantenimiento | B29: horas | C29: =Supuestos!$C$61+C14/100*Supuestos!$C$62 -> 80.4998 | D29: =Supuestos!$C$61+D14/100*Supuestos!$C$62 -> 80.75 | E29: =Supuestos!$C$61+E14/100*Supuestos!$C$62 -> 81.2498 | F29: =Supuestos!$C$61+F14/100*Supuestos!$C$62 -> 81.7502 | G29: =Supuestos!$C$61+G14/100*Supuestos!$C$62 -> 82.25 | H29: =Supuestos!$C$61+H14/100*Supuestos!$C$62 -> 82.7498 | I29: =Supuestos!$C$61+I14/100*Supuestos!$C$62 -> 83.2502 | J29: =Supuestos!$C$61+J14/100*Supuestos!$C$62 -> 84.0002 | ... BJ29: =Supuestos!$C$61+BJ14/100*Supuestos!$C$62 -> 140
A30: Horas requeridas | B30: horas | C30: =SUM(C26:C29) -> 140.809 | D30: =SUM(D26:D29) -> 115.98212 | E30: =SUM(E26:E29) -> 149.124 | F30: =SUM(F26:F29) -> 154.73812 | G30: =SUM(G26:G29) -> 160.21288 | H30: =SUM(H26:H29) -> 165.754 | I30: =SUM(I26:I29) -> 171.36812 | J30: =SUM(J26:J29) -> 207.28388 | ... BJ30: =SUM(BJ26:BJ29) -> 883.425
A31: Capacidad de los fundadores | B31: horas | C31: =Supuestos!$C$51*IF(C6=1,Supuestos!$C$54,IF(C6=2,Supuestos!$C$55,Supuestos!$C$56)) -> 240 | D31: =Supuestos!$C$51*IF(D6=1,Supuestos!$C$54,IF(D6=2,Supuestos!$C$55,Supuestos!$C$56)) -> 240 | E31: =Supuestos!$C$51*IF(E6=1,Supuestos!$C$54,IF(E6=2,Supuestos!$C$55,Supuestos!$C$56)) -> 240 | F31: =Supuestos!$C$51*IF(F6=1,Supuestos!$C$54,IF(F6=2,Supuestos!$C$55,Supuestos!$C$56)) -> 240 | G31: =Supuestos!$C$51*IF(G6=1,Supuestos!$C$54,IF(G6=2,Supuestos!$C$55,Supuestos!$C$56)) -> 240 | H31: =Supuestos!$C$51*IF(H6=1,Supuestos!$C$54,IF(H6=2,Supuestos!$C$55,Supuestos!$C$56)) -> 240 | I31: =Supuestos!$C$51*IF(I6=1,Supuestos!$C$54,IF(I6=2,Supuestos!$C$55,Supuestos!$C$56)) -> 240 | J31: =Supuestos!$C$51*IF(J6=1,Supuestos!$C$54,IF(J6=2,Supuestos!$C$55,Supuestos!$C$56)) -> 240 | ... BJ31: =Supuestos!$C$51*IF(BJ6=1,Supuestos!$C$54,IF(BJ6=2,Supuestos!$C$55,Supuestos!$C$56)) -> 480
